Workbook
Name Slicer_Elementary: #N/A
Name Slicer_Secondary: #N/A

Sheet NIF 4.c.1
A1: 4.c.1: Proportion of trained teachers, by education level (primary, upper primary, elementary, secondary and higher secondary education)
A2: State/UT | B2: 2015-16 | F2: 2016-17 | J2: 2017-18 | N2: 2018-19
B3: Primary | C3: Upper Primary | D3: Secondary | E3: Higher Secondary | F3: Primary | G3: Upper Primary | H3: Secondary | I3: Higher Secondary | J3: Primary | K3: Upper Primary | L3: Secondary | M3: Higher Secondary | N3: Primary | O3: Upper Primary | P3: Secondary
A4: Andaman & Nicobar Islands | B4: 94.966443 | C4: 82.539683 | D4: 87.87234 | E4: NA | F4: 94.669421 | G4: 83.762887 | H4: 87.863071 | I4: 98.96 | J4: 95.050559 | K4: 86.015038 | L4: 86.754297 | M4: 98.95 | N4: 96.183953 | O4: 82.018479 | P4: 85.054773 | Q4: Return to Index Page
A5: Andhra Pradesh | B5: 94.715486 | C5: 93.149173 | D5: 94.200689 | E5: 71.38 | F5: 94.458705 | G5: 92.744756 | H5: 94.457639 | I5: 98.7 | J5: 94.399096 | K5: 92.646251 | L5: 94.213171 | M5: 80.89 | N5: 84.103222 | O5: 74.216818 | P5: 75.176596
A6: Arunachal Pradesh | B6: 27.407644 | C6: 42.331478 | D6: 70.578444 | E6: 36.84 | F6: 27.745392 | G6: 42.283488 | H6: 69.995973 | I6: 73.52 | J6: 26.216555 | K6: 40.963196 | L6: 70.3125 | M6: 79.68 | N6: 56.493052 | O6: 64.322005 | P6: 79.036496
A7: Assam | B7: 20.59313 | C7: 11.367461 | D7: 14.337326 | E7: 11.22 | F7: 22.86107 | G7: 11.530515 | H7: 15.088599 | I7: 24.11 | J7: 24.916104 | K7: 11.79677 | L7: 17.285155 | M7: 27.79 | N7: 38.473786 | O7: 26.163744 | P7: 29.294607
A8: Bihar | B8: 27.196961 | C8: 44.991137 | D8: 65.339062 | E8: 11.47 | F8: 25.513203 | G8: 43.997267 | H8: 69.018114 | I8: 35.35 | J8: 21.438635 | K8: 29.304974 | L8: 67.184149 | M8: 66.17 | N8: 58.129327 | O8: 56.223739 | P8: 78.442195
A9: Chandigarh | B9: 94.029851 | C9: 91.444092 | D9: 89.996804 | E9: NA | F9: 92.305216 | G9: 89.583333 | H9: 90.308106 | I9: 98.92 | J9: 90.541052 | K9: 84.84328 | L9: 89.524934 | M9: 99.06 | N9: 89.417614 | O9: 85.796345 | P9: 89.493136
A10: Chhattisgarh | B10: 67.625189 | C10: 72.171054 | D10: 68.625998 | E10: 46.39 | F10: 70.089643 | G10: 73.228644 | H10: 69.854918 | I10: 63.02 | J10: 70.265401 | K10: 74.73418 | L10: 65.311175 | M10: 62.07 | N10: 76.224302 | O10: 76.210529 | P10: 78.029845
A11: Dadra & Nagar Haveli | B11: 87.752054 | C11: 90.760234 | D11: 87.323944 | E11: 100 | F11: 85.172171 | G11: 90.347924 | H11: 88.501027 | I11: 88.48 | J11: 83.469945 | K11: 90.092166 | L11: 91.146881 | M11: 89.93 | N11: 83.927371 | O11: 90.47619 | P11: 89.344262
A12: Daman & Diu | B12: 81.007752 | C12: 81.489362 | D12: 90.76087 | E12: 100 | F12: 82.142857 | G12: 79.006772 | H12: 87.121212 | I12: 91.07 | J12: 80.225989 | K12: 78.132118 | L12: 87.526427 | M12: 91.12 | N12: 79.886148 | O12: 74.473068 | P12: 83.840749
A13: Delhi | B13: 92.127297 | C13: 90.524936 | D13: 92.110847 | E13: 100 | F13: 92.087787 | G13: 89.938575 | H13: 91.487753 | I13: 100 | J13: 91.406949 | K13: 89.205282 | L13: 91.582021 | M13: 100 | N13: 90.186689 | O13: 87.227019 | P13: 89.329375
A14: Goa | B14: 85.515566 | C14: 88.950276 | D14: 89.345992 | E14: 96.65 | F14: 85.517708 | G14: 89.356605 | H14: 88.935833 | I14: 95.41 | J14: 80.030389 | K14: 88.179987 | L14: 87.302819 | M14: 93.88 | N14: 82.248793 | O14: 88.693694 | P14: 85.699352
A15: Gujarat | B15: 89.96472 | C15: 92.44111 | D15: 91.737267 | E15: 99.05 | F15: 90.178131 | G15: 92.812729 | H15: 91.762187 | I15: 99.91 | J15: 89.071836 | K15: 92.509402 | L15: 91.900209 | M15: 99.98 | N15: 89.687398 | O15: 92.880123 | P15: 91.79559
A16: Haryana | B16: 90.042453 | C16: 88.380738 | D16: 90.995857 | E16: 100 | F16: 89.868949 | G16: 87.722827 | H16: 90.939298 | I16: 95.86 | J16: 90.158555 | K16: 86.812409 | L16: 90.196999 | M16: 96.18 | N16: 88.823682 | O16: 86.171152 | P16: 89.09837
A17: Himachal Pradesh | B17: 83.544718 | C17: 77.618003 | D17: 83.834533 | E17: 92.47 | F17: 84.544871 | G17: 78.258062 | H17: 79.40214 | I17: 95.96 | J17: 85.367366 | K17: 79.603836 | L17: 83.992351 | M17: 96.59 | N17: 86.986387 | O17: 76.043602 | P17: 79.551685
A18: Jammu & Kashmir | B18: 41.702699 | C18: 58.924852 | D18: 78.718765 | E18: 77.08 | F18: 43.036718 | G18: 60.370456 | H18: 79.094773 | I18: 74.52 | J18: 44.328024 | K18: 56.98354 | L18: 79.351374 | M18: 73.57 | N18: 47.793715 | O18: 61.463689 | P18: 80.093778
A19: Jharkhand | B19: 30.762191 | C19: 46.179076 | D19: 69.746279 | E19: 49.5 | F19: 30.50537 | G19: 45.523922 | H19: 69.689357 | I19: 74.67 | J19: 24.438717 | K19: 33.422875 | L19: 72.736318 | M19: 77.36 | N19: 26.895955 | O19: 35.444754 | P19: 80.121043
A20: Karnataka | B20: 93.402944 | C20: 93.532069 | D20: 91.870403 | E20: 71.82 | F20: 57.771644 | G20: 59.070684 | H20: 70.233284 | I20: 80.98 | J20: 57.864556 | K20: 59.120038 | L20: 70.329609 | M20: 84.98 | N20: 93.005438 | O20: 93.308604 | P20: 92.134785
A21: Kerla | B21: 91.297218 | C21: 91.562034 | D21: 93.936083 | E21: 96.31 | F21: 91.525149 | G21: 91.598462 | H21: 94.086439 | I21: 97.61 | J21: 91.322526 | K21: 91.48345 | L21: 94.299713 | M21: 98.14 | N21: 91.918415 | O21: 92.106247 | P21: 94.526443
A22: Lakshadweep | B22: 96.825397 | C22: 86.792453 | D22: 87.00565 | E22: NA | F22: 95.942029 | G22: 84.710744 | H22: 80.381471 | I22: 94.27 | J22: 96.042216 | K22: 87.190083 | L22: 83.526012 | M22: 95.56 | N22: 94.561934 | O22: 88.888889 | P22: 86.206897
A23: Madhya Pradesh | B23: 72.980026 | C23: 70.025926 | D23: 76.495185 | E23: 47.62 | F23: 73.449208 | G23: 70.361643 | H23: 78.380152 | I23: 72.88 | J23: 84.296867 | K23: 60.626267 | L23: 79.046645 | M23: 73.01 | N23: 85.953682 | O23: 63.385595 | P23: 81.190372
A24: Maharashtra | B24: 96.057579 | C24: 96.937035 | D24: 97.57745 | E24: 98.29 | F24: 95.219596 | G24: 93.722647 | H24: 94.990487 | I24: 99.16 | J24: 94.449775 | K24: 92.630126 | L24: 94.223786 | M24: 98.96 | N24: 93.216994 | O24: 91.411221 | P24: 93.824715
A25: Manipur | B25: 30.726416 | C25: 29.5053 | D25: 44.833476 | E25: 42.63 | F25: 23.496584 | G25: 27.735268 | H25: 44.035013 | I25: 49.75 | J25: 21.829015 | K25: 23.244094 | L25: 38.277805 | M25: 47.96 | N25: 52.493426 | O25: 47.218716 | P25: 55.5018
A26: Meghalaya | B26: 17.925474 | C26: 14.652217 | D26: 36.706073 | E26: 26.28 | F26: 17.902344 | G26: 14.912388 | H26: 37.185317 | I26: 44.03 | J26: 17.431444 | K26: 15.024327 | L26: 38.721528 | M26: 44.79 | N26: 25.784039 | O26: 28.35999 | P26: 43.627352
A27: Mizoram | B27: 58.325324 | C27: 63.959441 | D27: 54.278562 | E27: 49.22 | F27: 27.278072 | G27: 28.421877 | H27: 41.399159 | I27: 48.52 | J27: 24.88397 | K27: 28.151986 | L27: 49.415068 | M27: 49.88 | N27: 69.884268 | O27: 74.828031 | P27: 61.32508
A28: Nagaland | B28: 17.962297 | C28: 18.471747 | D28: 29.977903 | E28: 14.12 | F28: 18.076923 | G28: 19.400597 | H28: 32.595141 | I28: 34.25 | J28: 19.657151 | K28: 20.594966 | L28: 33.173269 | M28: 37.24 | N28: 25.831988 | O28: 26.278936 | P28: 36.026743
A29: Orissa | B29: 74.735774 | C29: 74.697767 | D29: 76.109933 | E29: 31.51 | F29: 76.050955 | G29: 76.487802 | H29: 77.399171 | I29: 51.14 | J29: 75.081969 | K29: 77.501895 | L29: 77.605803 | M29: 53.34 | N29: 74.086754 | O29: 81.317131 | P29: 75.815381
A30: Puducherry | B30: 95.63885 | C30: 93.058734 | D30: 94.583851 | E30: 100 | F30: 98.380399 | G30: 93.764087 | H30: 94.859703 | I30: 99.8 | J30: 92.160695 | K30: 89.86463 | L30: 93.642785 | M30: 99 | N30: 92.296451 | O30: 87.852981 | P30: 92.570579
A31: Punjab | B31: 79.438879 | C31: 79.853209 | D31: 80.538895 | E31: 81.27 | F31: 80.083474 | G31: 80.123549 | H31: 80.227244 | I31: 93.3 | J31: 73.75227 | K31: 75.887086 | L31: 80.564055 | M31: 94.88 | N31: 73.484206 | O31: 88.251083 | P31: 86.847927
A32: Rajasthan | B32: 86.967839 | C32: 90.074238 | D32: 92.169881 | E32: NA | F32: 86.858239 | G32: 89.80826 | H32: 92.403535 | I32: 95.8 | J32: 87.503542 | K32: 90.864715 | L32: 93.442739 | M32: 96.18 | N32: 79.271813 | O32: 86.961304 | P32: 92.229495
A33: Sikkim | B33: 33.027418 | C33: 40.68641 | D33: 52.510849 | E33: NA | F33: 33.004813 | G33: 40.68641 | H33: 52.510849 | I33: 54.96 | J33: 34.709432 | K33: 37.555938 | L33: 54.98008 | M33: 60.32 | N33: 39.381579 | O33: 52.881976 | P33: 63.923182
A34: Tamilnadu | B34: 90.761758 | C34: 91.105269 | D34: 94.592111 | E34: 95.57 | F34: 91.036411 | G34: 91.558319 | H34: 94.959065 | I34: 97.64 | J34: 91.795322 | K34: 92.331226 | L34: 95.484743 | M34: 98.66 | N34: 85.322538 | O34: 89.590294 | P34: 93.306821
A35: Telangana | B35: 94.815282 | C35: 95.254673 | D35: 96.809275 | E35: 87.7 | F35: 95.22217 | G35: 95.269446 | H35: 96.882208 | I35: 91.69 | J35: 90.696625 | K35: 88.824329 | L35: 93.74852 | M35: 92.92 | N35: 86.99535 | O35: 81.61449 | P35: 90.95662
A36: Tripura | B36: 15.742822 | C36: 17.841795 | D36: 29.394474 | E36: NA | F36: 15.147176 | G36: 17.172935 | H36: 28.823195 | I36: 56.97 | J36: 14.720896 | K36: 20.46493 | L36: 34.127506 | M36: 59.08 | N36: 10.436032 | O36: 26.976496 | P36: 45.795988
A37: Uttar Pradesh | B37: 62.838801 | C37: 76.153205 | D37: 70.495462 | E37: 47.06 | F37: 65.702636 | G37: 75.721534 | H37: 70.715742 | I37: 75.19 | J37: 65.824702 | K37: 71.028123 | L37: 70.807393 | M37: 77.82 | N37: 70.622609 | O37: 72.42218 | P37: 73.857399
A38: Uttarakhand | B38: 71.583378 | C38: 82.769205 | D38: 90.736392 | E38: 93.08 | F38: 73.05547 | G38: 82.370612 | H38: 91.102892 | I38: 94.36 | J38: 67.784494 | K38: 77.994169 | L38: 90.542698 | M38: 93.83 | N38: 70.502787 | O38: 79.513954 | P38: 89.782495
A39: West Bengal | B39: 24.259348 | C39: 52.984834 | D39: 73.436182 | E39: 77.39 | F39: 27.477399 | G39: 53.686202 | H39: 74.703329 | I39: 68.75 | J39: 31.135787 | K39: 52.601314 | L39: 78.914795 | M39: 72.39 | N39: 33.359849 | O39: 54.768637 | P39: 81.140537
A40: All India | B40: 67.8198 | C40: 74.564033 | D40: 81.601188 | E40: 64.45 | F40: 67.217917 | G40: 72.621535 | H40: 79.957967 | I40: 84.21 | J40: 68.308786 | K40: 65.716505 | L40: 80.41895 | M40: 87.24 | N40: 71.67724 | O40: 72.274352 | P40: 82.622735
...

Sheet NIF 4.a.1 - 2018-19
A1: 4.a.1: Proportion of schools with access to: (a) electricity; (b) computers for pedagogical purposes; (c) adapted infrastructure and materials for students with disabilities/ disabled friendly ramp and toilets; (d) basic drinking water; (e) single-sex basic sanitation facilities; and (f) basic hand washing facilities (as per the WASH indicator definitions)
A2: State/UT | B2: 2018-19
B3: (a) Electricity | C3: (b) Computers for pedagogical purposes | D3: (c) Adapted infrastructure and materials for students with disabilities/disabled friendly ramp and toilets | F3: (d) Basic drinking water | G3: (e) Single-sex basic sanitation facilities | I3: (f) Basic hand washing facilities (as per the WASH indicator definitions)
D4: Toilets | E4: Ramp | G4: Boys | H4: Girls
A5: Andaman and Nicobar Islands | B5: 92.270531 | C5: 52.173913 | D5: 20.048309 | E5: 47.342995 | F5: 99.758454 | G5: 98.550725 | H5: 99.275362 | I5: 98.309179 | J5: Return to Index Page
A6: Andhra Pradesh | B6: 93.055752 | C6: 28.875686 | D6: 2.4755977 | E6: 37.732824 | F6: 89.464171 | G6: 88.629541 | H6: 96.395844 | I6: 81.675862
A7: Arunachal Pradesh | B7: 39.810177 | C7: 15.423148 | D7: 5.6156077 | E7: 20.45874 | F7: 62.061693 | G7: 70.023728 | H7: 70.181914 | I7: 27.998945
A8: Assam | B8: 30.15952 | C8: 13.958748 | D8: 13.467222 | E8: 56.225499 | F8: 88.868283 | G8: 73.33846 | H8: 75.105542 | I8: 78.915626
A9: Bihar | B9: 77.745898 | C9: 11.075495 | D9: 10.69219 | E9: 70.258002 | F9: 99.560656 | G9: 96.890971 | H9: 97.678876 | I9: 81.315565
A10: Chandigarh | B10: 100 | C10: 98.253275 | D10: 59.825328 | E10: 71.179039 | F10: 100 | G10: 98.689956 | H10: 99.563319 | I10: 100
A11: Chhattisgarh | B11: 80.824182 | C11: 93.11938 | D11: 53.618012 | E11: 63.428937 | F11: 99.251875 | G11: 96.611224 | H11: 97.29893 | I11: 92.804848
A12: Dadra and Nagar Haveli | B12: 100 | C12: 72.83237 | D12: 75.144509 | E12: 82.65896 | F12: 100 | G12: 93.063584 | H12: 94.797688 | I12: 99.710983
A13: Daman and Diu | B13: 100 | C13: 92.857143 | D13: 46.428571 | E13: 80.714286 | F13: 100 | G13: 96.428571 | H13: 95.714286 | I13: 98.571429
A14: Delhi | B14: 100 | C14: 92.425039 | D14: 87.866035 | E14: 74.346835 | F14: 100 | G14: 87.269858 | H14: 83.131685 | I14: 99.964931
A15: Goa | B15: 99.932705 | C15: 48.788694 | D15: 3.7685061 | E15: 53.903096 | F15: 100 | G15: 99.192463 | H15: 99.259758 | I15: 99.932705
A16: Gujarat | B16: 99.919386 | C16: 70.346824 | D16: 13.545007 | E16: 80.850479 | F16: 99.985343 | G16: 96.533592 | H16: 97.381873 | I16: 93.360327
A17: Haryana | B17: 97.917906 | C17: 48.028384 | D17: 27.096966 | E17: 63.040707 | F17: 99.715306 | G17: 92.806153 | H17: 95.572363 | I17: 98.406561
... A41: All India | B41: 73.856802 | C41: 32.655255 | D41: 17.539845 | E41: 63.707092 | F41: 95.684848 | G41: 92.626241 | H41: 94.383559 | I41: 88.183623
A42: Source: Department of School Education and Literacy, Ministry of Education / Periodicity: Annual

Sheet NIF 4.a.1 - 2017-18
A1: 4.a.1: Proportion of schools with access to: (a) electricity; (b) computers for pedagogical purposes; (c) adapted infrastructure and materials for students with disabilities/ disabled friendly ramp and toilets; (d) basic drinking water; (e) single-sex basic sanitation facilities; and (f) basic hand washing facilities (as per the WASH indicator definitions)
A2: State/UT | B2: 2017-18
B3: (a) Electricity | C3: (b) Computers for pedagogical purposes | D3: (c) Adapted infrastructure and materials for students with disabilities/disabled friendly ramp and toilets | F3: (d) Basic drinking water | G3: (e) Single-sex basic sanitation facilities | I3: (f) Basic hand washing facilities (as per the WASH indicator definitions)
D4: Toilets | E4: Ramp | G4: Boys | H4: Girls
A5: Andaman and Nicobar Islands | B5: 89.688249 | C5: 59.472422 | D5: 5.7553957 | E5: 32.134293 | F5: 98.081535 | G5: 99.760192 | H5: 100 | I5: 0 | J5: Return to Index Page
A6: Andhra Pradesh | B6: 92.797762 | C6: 33.231185 | D6: 0 | E6: 32.426571 | F6: 84.077444 | G6: 79.963227 | H6: 94.847013 | I6: 50.146936
A7: Arunachal Pradesh | B7: 37.503078 | C7: 26.225068 | D7: 1.3543462 | E7: 23.073135 | F7: 59.960601 | G7: 92.883526 | H7: 95.345974 | I7: 26.791431
A8: Assam | B8: 24.277234 | C8: 11.87962 | D8: 16.089215 | E8: 54.646251 | F8: 75.420246 | G8: 78.733697 | H8: 83.482691 | I8: 48.708582
A9: Bihar | B9: 45.817325 | C9: 13.351014 | D9: 5.5183435 | E9: 63.885394 | F9: 86.426847 | G9: 88.024889 | H9: 90.139744 | I9: 40.634456
A10: Chandigarh | B10: 100 | C10: 96.444444 | D10: 27.555556 | E10: 88 | F10: 100 | G10: 98.666667 | H10: 99.555556 | I10: 100
A11: Chhattisgarh | B11: 68.122799 | C11: 14.858952 | D11: 17.170369 | E11: 63.93049 | F11: 86.327416 | G11: 94.688912 | H11: 95.140692 | I11: 54.702785
A12: Dadra and Nagar Haveli | B12: 100 | C12: 82.369942 | D12: 30.924855 | E12: 78.612717 | F12: 99.421965 | G12: 99.710983 | H12: 100 | I12: 0
A13: Daman and Diu | B13: 98.601399 | C13: 86.013986 | D13: 8.3916084 | E13: 74.125874 | F13: 95.104895 | G13: 97.202797 | H13: 97.902098 | I13: 86.013986
A14: Delhi | B14: 99.930107 | C14: 90.459549 | D14: 71.186441 | E14: 74.121964 | F14: 100 | G14: 88.153067 | H14: 83.225581 | I14: 99.440853
A15: Goa | B15: 99.540984 | C15: 48.590164 | D15: 2.6229508 | E15: 51.344262 | F15: 100 | G15: 99.344262 | H15: 99.278689 | I15: 91.606557
A16: Gujarat | B16: 99.905802 | C16: 73.096175 | D16: 13.734508 | E16: 81.014388 | F16: 99.975989 | G16: 96.970872 | H16: 97.994126 | I16: 74.378013
A17: Haryana | B17: 97.520981 | C17: 50.776845 | D17: 10.294814 | E17: 63.580805 | F17: 99.694427 | G17: 93.638907 | H17: 96.389068 | I17: 87.006671
... A41: All India | B41: 63.0565 | C41: 31.250722 | D41: 8.0202553 | E41: 62.066789 | F41: 90.012893 | G41: 94.031008 | H41: 96.118581 | I41: 58.085622
A42: Source: Department of School Education and Literacy, Ministry of Education / Periodicity: Annual

Sheet NIF 4.a.1 - 2016-17
A1: 4.a.1: Proportion of schools with access to: (a) electricity; (b) computers for pedagogical purposes; (c) adapted infrastructure and materials for students with disabilities/ disabled friendly ramp and toilets; (d) basic drinking water; (e) single-sex basic sanitation facilities; and (f) basic hand washing facilities (as per the WASH indicator definitions)
A2: State/UT | B2: 2016-17
B3: (a) Electricity | C3: (b) Computers for pedagogical purposes | D3: (c) Adapted infrastructure and materials for students with disabilities/disabled friendly ramp and toilets | F3: (d) Basic drinking water | G3: (e) Single-sex basic sanitation facilities | I3: (f) Basic hand washing facilities (as per the WASH indicator definitions)
D4: Toilets | E4: Ramp | G4: Boys | H4: Girls
A5: Andaman and Nicobar Islands | B5: 87.951807 | C5: 56.63 | D5: 14.46 | E5: 29.39759 | F5: 96.626506 | G5: 99.759036 | H5: 100 | I5: 82.168675
A6: Andhra Pradesh | B6: 93.199844 | C6: 30.67 | D6: 7.86 | E6: 24.538422 | F6: 80.685216 | G6: 98.009037 | H6: 99.075218 | I6: 46.892472
A7: Arunachal Pradesh | B7: 36.002957 | C7: 24.82 | D7: 8.08 | E7: 22.621981 | F7: 58.846723 | G7: 93.297191 | H7: 95.933958 | I7: 25.18482
A8: Assam | B8: 23.926672 | C8: 11.23 | D8: 37.43 | E8: 55.520571 | F8: 71.074727 | G8: 78.998041 | H8: 83.215785 | I8: 46.88637
A9: Bihar | B9: 42.982745 | C9: 9.92 | D9: 12.08 | E9: 65.074975 | F9: 86.708175 | G9: 88.005226 | H9: 90.035545 | I9: 37.104823
A10: Chandigarh | B10: 100 | C10: 96.52 | D10: 55.22 | E10: 70.149254 | F10: 100 | G10: 98.507463 | H10: 99.502488 | I10: 100
A11: Chhattisgarh | B11: 70.717183 | C11: 13.49 | D11: 50.01 | E11: 66.214971 | F11: 89.62205 | G11: 99.096608 | H11: 99.303097 | I11: 56.745944
A12: Dadra and Nagar Haveli | B12: 99.711816 | C12: 62.54 | D12: 77.52 | E12: 75.216138 | F12: 98.270893 | G12: 99.711816 | H12: 100 | I12: 84.726225
A13: Daman and Diu | B13: 100 | C13: 84.83 | D13: 42.76 | E13: 68.275862 | F13: 97.241379 | G13: 97.931034 | H13: 98.62069 | I13: 77.241379
A14: Delhi | B14: 99.912755 | C14: 87.7 | D14: 70.3 | E14: 72.762171 | F14: 100 | G14: 88.815215 | H14: 83.214099 | I14: 99.371837
A15: Goa | B15: 99.871051 | C15: 45.97 | D15: 6.9 | E15: 48.549323 | F15: 97.356544 | G15: 99.355255 | H15: 99.355255 | I15: 90.006447
A16: Gujarat | B16: 99.911805 | C16: 75.77 | D16: 37.08 | E16: 80.720947 | F16: 99.964347 | G16: 97.162748 | H16: 98.177929 | I16: 67.033833
... A41: All India | B41: 60.81 | C41: 28.24 | D41: 22.44 | E41: 61.31101 | F41: 87.343727 | G41: 95.616726 | H41: 96.879807 | I41: 55.550433
A42: Source: Department of School Education and Literacy, Ministry of Education / Periodicity: Annual

Sheet School acess
A1: 4.a.1: Proportion of schools with access to: (a) electricity; (b) computers for pedagogical purposes; (c) adapted infrastructure and materials for students with disabilities/ disabled friendly ramp and toilets; (d) basic drinking water; (e) single-sex basic sanitation facilities; and (f) basic hand washing facilities (as per the WASH indicator definitions)
A2: State/UT | B2: 2015-16
B3: (a) Electricity | C3: (b) Computers for pedagogical purposes | D3: (c) Adapted infrastructure and materials for students with disabilities/disabled friendly ramp and toilets | F3: (d) Basic drinking water | G3: (e) Single-sex basic sanitation facilities | I3: (f) Basic hand washing facilities (as per the WASH indicator definitions)
D4: Toilets | E4: Ramp | G4: Boys | H4: Girls
A5: Andaman and Nicobar Islands | B5: 87.681159 | C5: 57 | D5: 13.285024 | E5: 27.294686 | F5: 96.376812 | G5: 99.758454 | H5: 100 | I5: 80.917874 | J5: Return to Index Page
A6: Andhra Pradesh | B6: 92.544097 | C6: 30.59 | D6: 7.8992696 | E6: 25.936972 | F6: 80.018181 | G6: 98.132436 | H6: 99.175465 | I6: 41.013046
A7: Arunachal Pradesh | B7: 35.137139 | C7: 24.36 | D7: 7.5611564 | E7: 21.86805 | F7: 57.845318 | G7: 93.723746 | H7: 96.417099 | I7: 23.424759
A8: Assam | B8: 22.925875 | C8: 10.76 | D8: 33.619549 | E8: 54.712705 | F8: 69.798148 | G8: 81.133696 | H8: 83.775795 | I8: 44.370936
A9: Bihar | B9: 35.874211 | C9: 9.37 | D9: 11.452348 | E9: 61.346693 | F9: 85.165487 | G9: 88.389762 | H9: 89.942542 | I9: 33.234009
A10: Chandigarh | B10: 100 | C10: 94.53 | D10: 39.303483 | E10: 59.701493 | F10: 100 | G10: 98.507463 | H10: 99.502488 | I10: 100
A11: Chhattisgarh | B11: 65.961957 | C11: 12.7 | D11: 48.554322 | E11: 65.456202 | F11: 89.196928 | G11: 96.389059 | H11: 97.558617 | I11: 52.129934
A12: Dadra and Nagar Haveli | B12: 99.711816 | C12: 42.65 | D12: 72.622478 | E12: 70.317003 | F12: 98.270893 | G12: 99.711816 | H12: 100 | I12: 78.386167
A13: Daman and Diu | B13: 100 | C13: 64.14 | D13: 32.413793 | E13: 66.206897 | F13: 97.241379 | G13: 97.931034 | H13: 98.62069 | I13: 70.344828
A14: Delhi | B14: 99.878367 | C14: 83.89 | D14: 69.556907 | E14: 73.327541 | F14: 100 | G14: 89.400521 | H14: 82.589053 | I14: 99.183319
A15: Goa | B15: 99.7426 | C15: 44.72 | D15: 6.3063063 | E15: 45.109395 | F15: 97.104247 | G15: 99.292149 | H15: 99.356499 | I15: 87.387387
A16: Gujarat | B16: 99.713872 | C16: 75.5 | D16: 29.862277 | E16: 78.984816 | F16: 98.332825 | G16: 97.178773 | H16: 98.210743 | I16: 60.052648
A17: Haryana | B17: 97.539771 | C17: 46.93 | D17: 38.400179 | E17: 62.240645 | F17: 97.15438 | G17: 93.336321 | H17: 96.074389 | I17: 79.605646
... A41: All India | B41: 58.548342 | C41: 27.31 | D41: 19.794646 | E41: 60.996084 | F41: 86.623439 | G41: 95.649204 | H41: 96.904047 | I41: 51.603713
A42: Source: Department of School Education and Literacy, Ministry of Education / Periodicity: Annual
H43: =AVERAGE(H5:H41) -> 96.80155 | I43: =SUM(I5:I41) -> 2085.1854

Sheet dashbaord

Sheet literacy rate
A1: 4.6.1: Literacy rate of youth in the age group of 15-24 years
A2: State/UT | B2: 2011
B3: Male | C3: Female | D3: Total
A4: Kerala | B4: 99.04 | C4: 99.03 | D4: 99.04 | F4: Return to Index Page
A5: Lakshadweep | B5: 98.28 | C5: 98.31 | D5: 98.3
A6: Puducherry | B6: 97.91 | C6: 97.08 | D6: 97.49
A7: Andaman and Nicobar Islands | B7: 97.07 | C7: 96.21 | D7: 96.66
A8: Himachal Pradesh | B8: 97.02 | C8: 95.77 | D8: 96.41
A9: Goa | B9: 96.65 | C9: 95.57 | D9: 96.15
A10: Tamil Nadu | B10: 97.16 | C10: 94.99 | D10: 96.09
A11: Sikkim | B11: 94.98 | C11: 93.38 | D11: 94.2
A12: Tripura | B12: 96.16 | C12: 92.45 | D12: 94.3
A13: Maharashtra | B13: 95.01 | C13: 92.13 | D13: 93.66
A14: Nct of Delhi | B14: 94.19 | C14: 91.93 | D14: 93.17
A15: Mizoram | B15: 95.12 | C15: 91.66 | D15: 93.4
A16: Chandigarh | B16: 93.21 | C16: 91.11 | D16: 92.31
... A39: Bihar | B39: 79.56 | C39: 63.69 | D39: 72.29
A40: Source: Office of the Registrar General & Census Commissioner, India, Ministry of Home Affairs / Periodicity: 10 Years

Sheet primary school
A1: 4.5.2: Enrolment ratio of children with disabilities
A2: State/UT | B2: 2018-19
B3: Primary | C3: Upper Primary | D3: Elementary | E3: Secondary | F3: Higher Secondary
A4: Andaman and Nicobar Islands | B4: 0.7139266 | C4: 0.88185354 | D4: 0.77767612 | E4: 0.80020216 | F4: 0.36540804 | H4: Return to Index Page
A5: Andhra Pradesh | B5: 1.3264498 | C5: 1.6759123 | D5: 1.454706 | E5: 1.3025334 | F5: 0.22312378
A6: Arunachal Pradesh | B6: 0.91599089 | C6: 0.90513212 | D6: 0.91228671 | E6: 0.49940198 | F6: 0.24771574
A7: Assam | B7: 1.1866258 | C7: 0.87936917 | D7: 1.0835794 | E7: 0.45803365 | F7: 0.25523602
A8: Bihar | B8: 0.55254791 | C8: 0.47170614 | D8: 0.52535724 | E8: 0.13147414 | F8: 0.074594179
A9: Chandigarh | B9: 1.6624027 | C9: 2.9531739 | D9: 2.1915869 | E9: 2.378505 | F9: 0.75340623
A10: Chhattisgarh | B10: 0.92061506 | C10: 0.82171088 | D10: 0.88448511 | E10: 0.47737438 | F10: 0.31615244
A11: Dadra and Nagar Haveli | B11: 2.6344967 | C11: 2.7173363 | D11: 2.6612245 | E11: 3.0012536 | F11: 2.0042758
A12: Daman and Diu | B12: 0.31448189 | C12: 0.64435468 | D12: 0.43084439 | E12: 0.44303797 | F12: 0.054749521
A13: Delhi | B13: 0.478514 | C13: 0.7383585 | D13: 0.57824935 | E13: 0.77930925 | F13: 0.47586438
A14: Goa | B14: 0.5634394 | C14: 1.1826507 | D14: 0.79095584 | E14: 0.98604999 | F14: 0.099648608
A15: Gujarat | B15: 0.92147545 | C15: 1.1350377 | D15: 1.0016493 | E15: 0.52313854 | F15: 0.41652326
A16: Haryana | B16: 0.56531852 | C16: 0.71107993 | D16: 0.61835412 | E16: 0.49433269 | F16: 0.22962983
... A40: All India (Total) | B40: 0.94678898 | C40: 1.0063248 | D40: 0.96752744 | E40: 0.64638261 | F40: 0.3083411
A41: Source: Department of School Education and Literacy, Ministry of Education / Periodicity: Annual

Sheet Sheet3
A3: Sum of Primary | B3: Sum of Upper Primary | C3: Sum of Elementary | D3: Sum of Secondary | E3: Sum of Higher Secondary
A4: 37.4267 | B4: 43.014107 | C4: 39.541067 | D4: 33.957373 | E4: 15.713653

Sheet daily excel report
C2: Day - 4 Vlookup
C3: Vlookup
A4: Name | B4: Primary | C4: Secondary | D4: Upper | E4: higher | F4: Higer secondary
A5: goa | B5: =VLOOKUP(A5,'disablites 2016'!A4:F40,2,FALSE) -> 1.94 | C5: =VLOOKUP(A5,'disablites 2016'!A4:F40,3,TRUE) -> 2.45 | D5: =VLOOKUP(A5,'disablites 2016'!A4:F40,4,FALSE) -> 2.13 | E5: =VLOOKUP(A5,'disablites 2016'!A4:F40,5,FALSE) -> 1.03 | F5: =VLOOKUP(A5,'disablites 2016'!A4:F40,6,FALSE) -> 0.28
A6: Column1 | B6: Column2 | C6: Column3
A7: 1001 | B7: ROM | C7: 500 | D7: Marks | E7: Grade
A8: 1005 | B8: Mouse | C8: 1200 | D8: 1040 | E8: =VLOOKUP(D8,Table8[#All],3,TRUE) -> 55000
A9: 1010 | B9: Laptop | C9: 25000 | D9: 1007
A10: 1020 | B10: Monitor | C10: 1000
A11: 1030 | B11: Keybaord | C11: 7000
A12: 1040 | B12: CPU | C12: 55000
A13: Product ID | B13: Product Name | C13: Price
A15: Column1 | B15: Column2 | C15: Hlookup | D15: Column3 | E15: Column4 | F15: Column5
A16: Name | B16: science | C16: english | D16: hindi | E16: social science | F16: computer science
A17: sneha mehta | B17: =HLOOKUP(A17,'Student Dataset (2)'!A2:J9,5,) -> 92 | C17: =HLOOKUP(A17,'Student Dataset (2)'!A2:EU9,6,) -> 70 | D17: =HLOOKUP(A17,'Student Dataset (2)'!A2:EU9,7,) -> 35 | E17: =HLOOKUP(A17,'Student Dataset (2)'!A2:EU9,8,) -> 55 | F17: =HLOOKUP(A17,'Student Dataset (2)'!A2:EU9,3,FALSE) -> 88
C19: if error formula
A21: products | B21: Amount | C21: qty | D21: Rate
A22: Products | B22: Amount | C22: Qty | D22: Rate
A23: CPU | B23: 254856 | C23: 12 | D23: =IFERROR(B23/C23,"-") -> 21238
A24: RAM | B24: 254685 | C24: 5 | D24: =IFERROR(B24/C24,"-") -> 50937
A25: ROM | B25: 25486 | C25: 85 | D25: =IFERROR(B25/C25,"-") -> 299.83529
A26: HDD | B26: 254156 | C26: 56 | D26: =IFERROR(B26/C26,"-") -> 4538.5
A27: Printer | B27: 65985 | D27: =IFERROR(B27/C27,"-") -> -
A28: Mouse | B28: 25469 | C28: 25 | D28: =IFERROR(B28/C28,"-") -> 1018.76
A29: Speaker | B29: 2564 | D29: =IFERROR(B29/C29,"-") -> -
A30: CD | B30: 54265 | C30: 96 | D30: =IFERROR(B30/C30,"-") -> 565.26042
A31: DVD | B31: 25463 | C31: 145 | D31: =IFERROR(B31/C31,"-") -> 175.6069
A32: Pen Drive | B32: 24521 | D32: =IFERROR(B32/C32,"-") -> -
C33: Day - 2
C34: Sum / average/min/max/count
A35: Products | B35: Amount | C35: Qty | D35: Sum | E35: Average | F35: Min | G35: Max | H35: Count | I35: Column1 | J35: Counta
A36: CPU | B36: 254856 | C36: 12 | D36: =SUM(B36:C36) -> 254868 | E36: =AVERAGE(B36:C36) -> 127434 | F36: =MIN(B36:C36) -> 12 | G36: =MAX(B36:C36) -> 254856 | H36: =COUNT(B36:C36) -> 2 | J36: =COUNTA(B36:C36) -> 2
A37: RAM | B37: 254685 | C37: 5 | D37: =SUM(B37:C37) -> 254690 | E37: =AVERAGE(B37:C37) -> 127345 | F37: =MIN(B37:C37) -> 5 | G37: =MAX(B37:C37) -> 254685 | H37: =COUNT(B37:C37) -> 2 | J37: =COUNTA(B37:C37) -> 2
A38: ROM | B38: 25486 | C38: 85 | D38: =SUM(B38:C38) -> 25571 | E38: =AVERAGE(B38:C38) -> 12785.5 | F38: =MIN(B38:C38) -> 85 | G38: =MAX(B38:C38) -> 25486 | H38: =COUNT(B38:C38) -> 2 | J38: =COUNTA(B38:C38) -> 2
A39: HDD | B39: 254156 | C39: 56 | D39: =SUM(B39:C39) -> 254212 | E39: =AVERAGE(B39:C39) -> 127106 | F39: =MIN(B39:C39) -> 56 | G39: =MAX(B39:C39) -> 254156 | H39: =COUNT(B39:C39) -> 2 | J39: =COUNTA(B39:C39) -> 2
A40: Printer | B40: 65985 | C40: 98 | D40: =SUM(B40:C40) -> 66083 | E40: =AVERAGE(B40:C40) -> 33041.5 | F40: =MIN(B40:C40) -> 98 | G40: =MAX(B40:C40) -> 65985 | H40: =COUNT(B40:C40) -> 2 | J40: =COUNTA(B40:C40) -> 2
A41: Mouse | B41: 25469 | C41: 25 | D41: =SUM(B41:C41) -> 25494 | E41: =AVERAGE(B41:C41) -> 12747 | F41: =MIN(B41:C41) -> 25 | G41: =MAX(B41:C41) -> 25469 | H41: =COUNT(B41:C41) -> 2 | J41: =COUNTA(B41:C41) -> 2
A42: Speaker | B42: 2564 | C42: 68 | D42: =SUM(B42:C42) -> 2632 | E42: =AVERAGE(B42:C42) -> 1316 | F42: =MIN(B42:C42) -> 68 | G42: =MAX(B42:C42) -> 2564 | H42: =COUNT(B42:C42) -> 2 | J42: =COUNTA(B42:C42) -> 2
A43: CD | B43: 54265 | C43: 96 | D43: =SUM(B43:C43) -> 54361 | E43: =AVERAGE(B43:C43) -> 27180.5 | F43: =MIN(B43:C43) -> 96 | G43: =MAX(B43:C43) -> 54265 | H43: =COUNT(B43:C43) -> 2 | J43: =COUNTA(B43:C43) -> 2
A44: DVD | B44: 25463 | C44: 145 | D44: =SUM(B44:C44) -> 25608 | E44: =AVERAGE(B44:C44) -> 12804 | F44: =MIN(B44:C44) -> 145 | G44: =MAX(B44:C44) -> 25463 | H44: =COUNT(B44:C44) -> 2 | J44: =COUNTA(B44:C44) -> 2
...

Sheet disablites 2017
A1: 4.5.2: Enrolment ratio of children with disabilities
A2: State/UT | B2: 2016-17
B3: Primary | C3: Upper Primary | D3: Elementary | E3: Secondary | F3: Higher Secondary
A4: Andaman and Nicobar Islands | B4: 0.9290045 | C4: 0.82308984 | D4: 0.88920541 | E4: 0.82066136 | F4: 0.61922454 | H4: Return to Index Page
A5: Andhra Pradesh | B5: 1.5100247 | C5: 1.4347593 | D5: 1.4818045 | E5: 1.1351827 | F5: 0
A6: Arunachal Pradesh | B6: 0.88715248 | C6: 1.0575768 | D6: 0.94419553 | E6: 0.57328307 | F6: 0.18555426
A7: Assam | B7: 1.4930541 | C7: 1.1896038 | D7: 1.3957288 | E7: 0.32514155 | F7: 0.12616457
A8: Bihar | B8: 0.85858694 | C8: 0.72382342 | D8: 0.81521349 | E8: 0.21275605 | F8: 0.085147634
A9: Chandigarh | B9: 1.7368536 | C9: 3.3288022 | D9: 2.3958107 | E9: 2.5927268 | F9: 0.8730776
A10: Chhattisgarh | B10: 1.4369003 | C10: 1.4442943 | D10: 1.439687 | E10: 0.37299871 | F10: 0.23731055
A11: Dadra and Nagar Haveli | B11: 0.76484992 | C11: 0.61483452 | D11: 0.70681511 | E11: 0.49594229 | F11: 0.31401656
A12: Daman and Diu | B12: 0.39306483 | C12: 0.53576744 | D12: 0.44326551 | E12: 0.42553191 | F12: 0.19701661
A13: Delhi | B13: 0.52162083 | C13: 0.81392327 | D13: 0.6318887 | E13: 0.77200171 | F13: 0.68014762
A14: Goa | B14: 1.4334778 | C14: 2.3746739 | D14: 1.7801058 | E14: 1.0307785 | F14: 0.30747653
A15: Gujarat | B15: 1.0653846 | C15: 1.2858657 | D15: 1.15091 | E15: 0.58772597 | F15: 0.4064731
A16: Haryana | B16: 0.62746523 | C16: 0.72650373 | D16: 0.66435689 | E16: 0.46975703 | F16: 0.23066722
... A40: All India (Total) | B40: 1.0921452 | C40: 1.1276678 | D40: 1.1045068 | E40: 0.56213894 | F40: 0.27689617
A41: Source: Department of School Education and Literacy, Ministry of Education / Periodicity: Annual

Sheet DASHBOARD
B2: Total Student
B4: =COUNTA(Student_Dataset[Student Name]) -> 150
P18: GRADE | Q18: Count | R18: Class Average | S18: Average
P19: A grade | Q19: =COUNTIF('Student Dataset'!M2:M32,"A GRADE") -> 7 | R19: 6A | S19: =AVERAGEIF(Student_Dataset[Class],"6A",Student_Dataset[Percentage]) -> 77.25
P20: B grade | Q20: =COUNTIF(Student_Dataset[[#Headers],[#Data],[Grade]],"B GRADE") -> 75 | R20: 6B | S20: =AVERAGEIF(Student_Dataset[Class],"6B",Student_Dataset[Percentage]) -> 82.221053
P21: C GRADE | Q21: =COUNTIF(Student_Dataset[[#Headers],[#Data],[Grade]],"C GRADE") -> 40 | R21: 7A | S21: =AVERAGEIF(Student_Dataset[Class],"7A",Student_Dataset[Percentage]) -> 78.571429
P22: D GRADE | Q22: =COUNTIF(Student_Dataset[[#Headers],[#Data],[Grade]],"D GRADE") -> 4 | R22: 7B | S22: =AVERAGEIF(Student_Dataset[Class],"7B",Student_Dataset[Percentage]) -> 77.275
R23: 8A | S23: =AVERAGEIF(Student_Dataset[Class],"8A",Student_Dataset[Percentage]) -> 80.966667
R24: 8B | S24: =AVERAGEIF(Student_Dataset[Class],"8B",Student_Dataset[Percentage]) -> 77.453333
R25: 9A | S25: =AVERAGEIF(Student_Dataset[Class],"9A",Student_Dataset[Percentage]) -> 84.616667
R26: 9B | S26: =AVERAGEIF(Student_Dataset[Class],"9B",Student_Dataset[Percentage]) -> 78.877778
R27: 10A | S27: =AVERAGEIF(Student_Dataset[Class],"10B",Student_Dataset[Percentage]) -> 81.4
R28: 10B | S28: =AVERAGEIF(Student_Dataset[Class],"10B",Student_Dataset[Percentage]) -> 81.4

Sheet Student Dataset
A1: Student ID | B1: Student Name | C1: Class | D1: Mathematics | E1: Science | F1: English | G1: Hindi | H1: Social Studies | I1: Computer Science | J1: Obtained Marks | K1: Total Marks | L1: Percentage | M1: Grade
A2: STU083 | B2: Reyansh Bhatia | C2: 6A | D2: 71 | E2: 95 | F2: 96 | G2: 91 | H2: 78 | I2: 58 | J2: =SUM(Student_Dataset[[#This Row],[Mathematics]:[Computer Science]]) -> 489 | K2: 500 | L2: =(J2/K2)*100 -> 97.8 | M2: =IF(L2>=90,"A Grade",IF(L2>=75,"B Grade",IF(L2>=60,"C Grade",IF(L2>=50,"D Grade","Fail")))) -> A Grade | P2: Column1 | Q2: Column2 | R2: Column3 | S2: Column4 | T2: Column5 | U2: Column6 | V2: Column7 | W2: Column8 | X2: Column9 | Y2: Column10 | Z2: Column11
A3: STU135 | B3: Meera Desai | C3: 6A | D3: 42 | E3: 96 | F3: 86 | G3: 89 | H3: 48 | I3: 97 | J3: =SUM(Student_Dataset[[#This Row],[Mathematics]:[Computer Science]]) -> 458 | K3: 500 | L3: =(J3/K3)*100 -> 91.6 | M3: =IF(L3>=90,"A Grade",IF(L3>=75,"B Grade",IF(L3>=60,"C Grade",IF(L3>=50,"D Grade","Fail")))) -> A Grade | P3: Section | Q3: Sum 6A | R3: Sum 6B | S3: Sum 7A | T3: Sum 7B | U3: Sum 8A | V3: Sum 8B | W3: Sum 9A | X3: Sum 9B | Y3: Sum 10A | Z3: Sum 10B
A4: STU117 | B4: Aarav Reddy | C4: 6A | D4: 98 | E4: 71 | F4: 64 | G4: 80 | H4: 63 | I4: 59 | J4: =SUM(Student_Dataset[[#This Row],[Mathematics]:[Computer Science]]) -> 435 | K4: 500 | L4: =(J4/K4)*100 -> 87 | M4: =IF(L4>=90,"A Grade",IF(L4>=75,"B Grade",IF(L4>=60,"C Grade",IF(L4>=50,"D Grade","Fail")))) -> B Grade | Q4: =SUMIF(C2:C151,"6A",Student_Dataset[[Mathematics]:[Computer Science]]) -> 982 | R4: =SUMIF(C2:C151,"6B",Student_Dataset[[Mathematics]:[Computer Science]]) -> 1267 | S4: =SUMIF(C2:C151,"7A",Student_Dataset[[Mathematics]:[Computer Science]]) -> 449 | T4: =SUMIF(C2:C151,"7B",Student_Dataset[[Mathematics]:[Computer Science]]) -> 464 | U4: =SUMIF(C2:C151,"8A",Student_Dataset[[Mathematics]:[Computer Science]]) -> 879 | V4: =SUMIF(C2:C151,"8B",Student_Dataset[[Mathematics]:[Computer Science]]) -> 995 | W4: =SUMIF(C2:C151,"9A",Student_Dataset[[Mathematics]:[Computer Science]]) -> 1737 | X4: =SUMIF(C2:C151,"9B",Student_Dataset[[Mathematics]:[Computer Science]]) -> 1069 | Y4: =SUMIF(C2:C151,"10A",Student_Dataset[[Mathematics]:[Computer Science]]) -> 1369 | Z4: =SUMIF(C2:C151,"10B",Student_Dataset[[Mathematics]:[Computer Science]]) -> 798
A5: STU114 | B5: Meera Chauhan | C5: 6A | D5: 94 | E5: 71 | F5: 55 | G5: 44 | H5: 91 | I5: 79 | J5: =SUM(Student_Dataset[[#This Row],[Mathematics]:[Computer Science]]) -> 434 | K5: 500 | L5: =(J5/K5)*100 -> 86.8 | M5: =IF(L5>=90,"A Grade",IF(L5>=75,"B Grade",IF(L5>=60,"C Grade",IF(L5>=50,"D Grade","Fail")))) -> B Grade | P5: Count if | Q5: =COUNTIF(Student_Dataset[Class],"6A") -> 16 | R5: =COUNTIF(Student_Dataset[Class],"6B") -> 19 | S5: =COUNTIF(Student_Dataset[Class],"7A") -> 7 | T5: =COUNTIF(Student_Dataset[],"7B") -> 8 | U5: =COUNTIF(Student_Dataset[],"8A") -> 12 | V5: =COUNTIF(Student_Dataset[],"8B") -> 15 | W5: =COUNTIF(Student_Dataset[],"9A") -> 24 | X5: =COUNTIF(Student_Dataset[],"9B") -> 18 | Y5: =COUNTIF(Student_Dataset[],"10A") -> 19 | Z5: =COUNTIF(Student_Dataset[],"10B") -> 12
A6: STU038 | B6: Darsh Verma | C6: 6A | D6: 77 | E6: 51 | F6: 68 | G6: 55 | H6: 91 | I6: 89 | J6: =SUM(Student_Dataset[[#This Row],[Mathematics]:[Computer Science]]) -> 431 | K6: 500 | L6: =(J6/K6)*100 -> 86.2 | M6: =IF(L6>=90,"A Grade",IF(L6>=75,"B Grade",IF(L6>=60,"C Grade",IF(L6>=50,"D Grade","Fail")))) -> B Grade
A7: STU133 | B7: Atharva Chauhan | C7: 6A | D7: 51 | E7: 88 | F7: 49 | G7: 43 | H7: 95 | I7: 92 | J7: =SUM(Student_Dataset[[#This Row],[Mathematics]:[Computer Science]]) -> 418 | K7: 500 | L7: =(J7/K7)*100 -> 83.6 | M7: =IF(L7>=90,"A Grade",IF(L7>=75,"B Grade",IF(L7>=60,"C Grade",IF(L7>=50,"D Grade","Fail")))) -> B Grade
A8: STU055 | B8: Ritvik Kumar | C8: 6A | D8: 48 | E8: 89 | F8: 63 | G8: 57 | H8: 94 | I8: 41 | J8: =SUM(Student_Dataset[[#This Row],[Mathematics]:[Computer Science]]) -> 392 | K8: 500 | L8: =(J8/K8)*100 -> 78.4 | M8: =IF(L8>=90,"A Grade",IF(L8>=75,"B Grade",IF(L8>=60,"C Grade",IF(L8>=50,"D Grade","Fail")))) -> B Grade
A9: STU125 | B9: Ayaan Kumar | C9: 6A | D9: 39 | E9: 73 | F9: 98 | G9: 49 | H9: 47 | I9: 65 | J9: =SUM(Student_Dataset[[#This Row],[Mathematics]:[Computer Science]]) -> 371 | K9: 500 | L9: =(J9/K9)*100 -> 74.2 | M9: =IF(L9>=90,"A Grade",IF(L9>=75,"B Grade",IF(L9>=60,"C Grade",IF(L9>=50,"D Grade","Fail")))) -> C Grade
A10: STU021 | B10: Arjun Jain | C10: 6A | D10: 64 | E10: 43 | F10: 39 | G10: 77 | H10: 44 | I10: 100 | J10: =SUM(Student_Dataset[[#This Row],[Mathematics]:[Computer Science]]) -> 367 | K10: 500 | L10: =(J10/K10)*100 -> 73.4 | M10: =IF(L10>=90,"A Grade",IF(L10>=75,"B Grade",IF(L10>=60,"C Grade",IF(L10>=50,"D Grade","Fail")))) -> C Grade
A11: STU030 | B11: Ishita Patel | C11: 6A | D11: 100 | E11: 45 | F11: 58 | G11: 43 | H11: 43 | I11: 65 | J11: =SUM(Student_Dataset[[#This Row],[Mathematics]:[Computer Science]]) -> 354 | K11: 500 | L11: =(J11/K11)*100 -> 70.8 | M11: =IF(L11>=90,"A Grade",IF(L11>=75,"B Grade",IF(L11>=60,"C Grade",IF(L11>=50,"D Grade","Fail")))) -> C Grade
A12: STU150 | B12: Aanya Iyer | C12: 6A | D12: 35 | E12: 61 | F12: 73 | G12: 62 | H12: 52 | I12: 67 | J12: =SUM(Student_Dataset[[#This Row],[Mathematics]:[Computer Science]]) -> 350 | K12: 500 | L12: =(J12/K12)*100 -> 70 | M12: =IF(L12>=90,"A Grade",IF(L12>=75,"B Grade",IF(L12>=60,"C Grade",IF(L12>=50,"D Grade","Fail")))) -> C Grade
A13: STU002 | B13: Deepika Tiwari | C13: 6A | D13: 38 | E13: 46 | F13: 62 | G13: 64 | H13: 99 | I13: 38 | J13: =SUM(Student_Dataset[[#This Row],[Mathematics]:[Computer Science]]) -> 347 | K13: 500 | L13: =(J13/K13)*100 -> 69.4 | M13: =IF(L13>=90,"A Grade",IF(L13>=75,"B Grade",IF(L13>=60,"C Grade",IF(L13>=50,"D Grade","Fail")))) -> C Grade
A14: STU001 | B14: Mohammed Singh | C14: 6A | D14: 70 | E14: 66 | F14: 63 | G14: 52 | H14: 48 | I14: 46 | J14: =SUM(Student_Dataset[[#This Row],[Mathematics]:[Computer Science]]) -> 345 | K14: 500 | L14: =(J14/K14)*100 -> 69 | M14: =IF(L14>=90,"A Grade",IF(L14>=75,"B Grade",IF(L14>=60,"C Grade",IF(L14>=50,"D Grade","Fail")))) -> C Grade
A15: STU132 | B15: Ayaan Shah | C15: 6A | D15: 51 | E15: 36 | F15: 80 | G15: 65 | H15: 76 | I15: 37 | J15: =SUM(Student_Dataset[[#This Row],[Mathematics]:[Computer Science]]) -> 345 | K15: 500 | L15: =(J15/K15)*100 -> 69 | M15: =IF(L15>=90,"A Grade",IF(L15>=75,"B Grade",IF(L15>=60,"C Grade",IF(L15>=50,"D Grade","Fail")))) -> C Grade
A16: STU145 | B16: Diya Mishra | C16: 6A | D16: 58 | E16: 53 | F16: 86 | G16: 43 | H16: 53 | I16: 38 | J16: =SUM(Student_Dataset[[#This Row],[Mathematics]:[Computer Science]]) -> 331 | K16: 500 | L16: =(J16/K16)*100 -> 66.2 | M16: =IF(L16>=90,"A Grade",IF(L16>=75,"B Grade",IF(L16>=60,"C Grade",IF(L16>=50,"D Grade","Fail")))) -> C Grade
A17: STU093 | B17: Nandini Chauhan | C17: 6A | D17: 46 | E17: 64 | F17: 37 | G17: 69 | H17: 40 | I17: 57 | J17: =SUM(Student_Dataset[[#This Row],[Mathematics]:[Computer Science]]) -> 313 | K17: 500 | L17: =(J17/K17)*100 -> 62.6 | M17: =IF(L17>=90,"A Grade",IF(L17>=75,"B Grade",IF(L17>=60,"C Grade",IF(L17>=50,"D Grade","Fail")))) -> C Grade
... A31: STU024 | B31: Imran Desai | C31: 6B | D31: 42 | E31: 86 | F31: 78 | G31: 48 | H31: 66 | I31: 59 | J31: =SUM(Student_Dataset[[#This Row],[Mathematics]:[Computer Science]]) -> 379 | K31: 500 | L31: =(J31/K31)*100 -> 75.8 | M31: =IF(L31>=90,"A Grade",IF(L31>=75,"B Grade",IF(L31>=60,"C Grade",IF(L31>=50,"D Grade","Fail")))) -> B Grade
A32: STU048 | B32: Priya Tiwari | C32: 6B | D32: 77 | E32: 75 | F32: 50 | G32: 73 | H32: 99 | J32: =SUM(Student_Dataset[[#This Row],[Mathematics]:[Computer Science]]) -> 374 | K32: 500 | L32: =(J32/K32)*100 -> 74.8 | M32: =IF(L32>=90,"A Grade",IF(L32>=75,"B Grade",IF(L32>=60,"C Grade",IF(L32>=50,"D Grade","Fail")))) -> C Grade
A33: STU069 | B33: Nandini Iyer | C33: 6B | D33: 55 | E33: 74 | F33: 48 | G33: 38 | H33: 74 | I33: 83 | J33: =SUM(Student_Dataset[[#This Row],[Mathematics]:[Computer Science]]) -> 372 | K33: 500 | L33: =(J33/K33)*100 -> 74.4 | M33: =IF(L33>=90,"A Grade",IF(L33>=75,"B Grade",IF(L33>=60,"C Grade",IF(L33>=50,"D Grade","Fail")))) -> C Grade
A34: STU039 | B34: Sneha Sharma | C34: 6B | D34: 44 | E34: 54 | F34: 39 | G34: 82 | H34: 53 | I34: 90 | J34: =SUM(Student_Dataset[[#This Row],[Mathematics]:[Computer Science]]) -> 362 | K34: 500 | L34: =(J34/K34)*100 -> 72.4 | M34: =IF(L34>=90,"A Grade",IF(L34>=75,"B Grade",IF(L34>=60,"C Grade",IF(L34>=50,"D Grade","Fail")))) -> C Grade
A35: STU087 | B35: Ruhi Saxena | C35: 6B | D35: 61 | E35: 62 | F35: 68 | G35: 45 | H35: 55 | I35: 65 | J35: =SUM(Student_Dataset[[#This Row],[Mathematics]:[Computer Science]]) -> 356 | K35: 500 | L35: =(J35/K35)*100 -> 71.2 | M35: =IF(L35>=90,"A Grade",IF(L35>=75,"B Grade",IF(L35>=60,"C Grade",IF(L35>=50,"D Grade","Fail")))) -> C Grade
A36: STU067 | B36: Kabir Desai | C36: 6B | D36: 40 | E36: 38 | F36: 66 | G36: 60 | H36: 37 | I36: 54 | J36: =SUM(Student_Dataset[[#This Row],[Mathematics]:[Computer Science]]) -> 295 | K36: 500 | L36: =(J36/K36)*100 -> 59 | M36: =IF(L36>=90,"A Grade",IF(L36>=75,"B Grade",IF(L36>=60,"C Grade",IF(L36>=50,"D Grade","Fail")))) -> D Grade
A37: STU011 | B37: Ishaan Chauhan | C37: 7A | D37: 66 | E37: 68 | F37: 89 | G37: 86 | H37: 81 | I37: 63 | J37: =SUM(Student_Dataset[[#This Row],[Mathematics]:[Computer Science]]) -> 453 | K37: 500 | L37: =(J37/K37)*100 -> 90.6 | M37: =IF(L37>=90,"A Grade",IF(L37>=75,"B Grade",IF(L37>=60,"C Grade",IF(L37>=50,"D Grade","Fail")))) -> A Grade
A38: STU052 | B38: Kiara Kapoor | C38: 7A | D38: 45 | E38: 71 | F38: 100 | G38: 77 | H38: 46 | I38: 65 | J38: =SUM(Student_Dataset[[#This Row],[Mathematics]:[Computer Science]]) -> 404 | K38: 500 | L38: =(J38/K38)*100 -> 80.8 | M38: =IF(L38>=90,"A Grade",IF(L38>=75,"B Grade",IF(L38>=60,"C Grade",IF(L38>=50,"D Grade","Fail")))) -> B Grade
A39: STU050 | B39: Imran Saxena | C39: 7A | D39: 73 | E39: 86 | F39: 35 | G39: 73 | H39: 71 | I39: 61 | J39: =SUM(Student_Dataset[[#This Row],[Mathematics]:[Computer Science]]) -> 399 | K39: 500 | L39: =(J39/K39)*100 -> 79.8 | M39: =IF(L39>=90,"A Grade",IF(L39>=75,"B Grade",IF(L39>=60,"C Grade",IF(L39>=50,"D Grade","Fail")))) -> B Grade
A40: STU016 | B40: Nandini Mehta | C40: 7A | D40: 82 | E40: 55 | F40: 35 | G40: 76 | H40: 97 | I40: 37 | J40: =SUM(Student_Dataset[[#This Row],[Mathematics]:[Computer Science]]) -> 382 | K40: 500 | L40: =(J40/K40)*100 -> 76.4 | M40: =IF(L40>=90,"A Grade",IF(L40>=75,"B Grade",IF(L40>=60,"C Grade",IF(L40>=50,"D Grade","Fail")))) -> B Grade
A41: STU118 | B41: Ruhi Chauhan | C41: 7A | D41: 47 | E41: 40 | F41: 74 | G41: 91 | H41: 39 | I41: 81 | J41: =SUM(Student_Dataset[[#This Row],[Mathematics]:[Computer Science]]) -> 372 | K41: 500 | L41: =(J41/K41)*100 -> 74.4 | M41: =IF(L41>=90,"A Grade",IF(L41>=75,"B Grade",IF(L41>=60,"C Grade",IF(L41>=50,"D Grade","Fail")))) -> C Grade
A42: STU082 | B42: Sameer Nair | C42: 7A | D42: 70 | E42: 40 | F42: 41 | G42: 72 | H42: 51 | I42: 97 | J42: =SUM(Student_Dataset[[#This Row],[Mathematics]:[Computer Science]]) -> 371 | K42: 500 | L42: =(J42/K42)*100 -> 74.2 | M42: =IF(L42>=90,"A Grade",IF(L42>=75,"B Grade",IF(L42>=60,"C Grade",IF(L42>=50,"D Grade","Fail")))) -> C Grade
A43: STU112 | B43: Priya Tiwari | C43: 7A | D43: 66 | E43: 87 | F43: 58 | G43: 56 | H43: 57 | I43: 45 | J43: =SUM(Student_Dataset[[#This Row],[Mathematics]:[Computer Science]]) -> 369 | K43: 500 | L43: =(J43/K43)*100 -> 73.8 | M43: =IF(L43>=90,"A Grade",IF(L43>=75,"B Grade",IF(L43>=60,"C Grade",IF(L43>=50,"D Grade","Fail")))) -> C Grade
A44: STU060 | B44: Aryan Kumar | C44: 7B | D44: 43 | E44: 88 | F44: 87 | G44: 77 | H44: 94 | I44: 88 | J44: =SUM(Student_Dataset[[#This Row],[Mathematics]:[Computer Science]]) -> 477 | K44: 500 | L44: =(J44/K44)*100 -> 95.4 | M44: =IF(L44>=90,"A Grade",IF(L44>=75,"B Grade",IF(L44>=60,"C Grade",IF(L44>=50,"D Grade","Fail")))) -> A Grade
... A76: STU004 | B76: Aryan Tiwari | C76: 8B | D76: 70 | E76: 54 | F76: 62 | G76: 78 | H76: 48 | I76: 46 | J76: =SUM(Student_Dataset[[#This Row],[Mathematics]:[Computer Science]]) -> 358 | K76: 500 | L76: =(J76/K76)*100 -> 71.6 | M76: =IF(L76>=90,"A Grade",IF(L76>=75,"B Grade",IF(L76>=60,"C Grade",IF(L76>=50,"D Grade","Fail")))) -> C Grade
A77: STU017 | B77: Ayaan Dhawan | C77: 8B | D77: 74 | E77: 65 | F77: 42 | G77: 65 | H77: 45 | J77: =SUM(Student_Dataset[[#This Row],[Mathematics]:[Computer Science]]) -> 291 | K77: 500 | L77: =(J77/K77)*100 -> 58.2 | M77: =IF(L77>=90,"A Grade",IF(L77>=75,"B Grade",IF(L77>=60,"C Grade",IF(L77>=50,"D Grade","Fail")))) -> D Grade
A78: STU147 | B78: Priya Yadav | C78: 8B | D78: 45 | E78: 41 | F78: 54 | G78: 55 | H78: 41 | I78: 45 | J78: =SUM(Student_Dataset[[#This Row],[Mathematics]:[Computer Science]]) -> 281 | K78: 500 | L78: =(J78/K78)*100 -> 56.2 | M78: =IF(L78>=90,"A Grade",IF(L78>=75,"B Grade",IF(L78>=60,"C Grade",IF(L78>=50,"D Grade","Fail")))) -> D Grade
A79: STU148 | B79: Darsh Pandey | C79: 9A | D79: 97 | E79: 67 | F79: 87 | G79: 67 | H79: 78 | I79: 98 | J79: =SUM(Student_Dataset[[#This Row],[Mathematics]:[Computer Science]]) -> 494 | K79: 500 | L79: =(J79/K79)*100 -> 98.8 | M79: =IF(L79>=90,"A Grade",IF(L79>=75,"B Grade",IF(L79>=60,"C Grade",IF(L79>=50,"D Grade","Fail")))) -> A Grade
A80: STU115 | B80: Deepika Yadav | C80: 9A | D80: 67 | E80: 93 | F80: 73 | G80: 60 | H80: 84 | I80: 96 | J80: =SUM(Student_Dataset[[#This Row],[Mathematics]:[Computer Science]]) -> 473 | K80: 500 | L80: =(J80/K80)*100 -> 94.6 | M80: =IF(L80>=90,"A Grade",IF(L80>=75,"B Grade",IF(L80>=60,"C Grade",IF(L80>=50,"D Grade","Fail")))) -> A Grade
A81: STU062 | B81: Rohan Malhotra | C81: 9A | D81: 88 | E81: 63 | F81: 97 | G81: 63 | H81: 69 | I81: 90 | J81: =SUM(Student_Dataset[[#This Row],[Mathematics]:[Computer Science]]) -> 470 | K81: 500 | L81: =(J81/K81)*100 -> 94 | M81: =IF(L81>=90,"A Grade",IF(L81>=75,"B Grade",IF(L81>=60,"C Grade",IF(L81>=50,"D Grade","Fail")))) -> A Grade
A82: STU065 | B82: Vihaan Chauhan | C82: 9A | D82: 76 | E82: 62 | F82: 93 | G82: 76 | H82: 78 | I82: 83 | J82: =SUM(Student_Dataset[[#This Row],[Mathematics]:[Computer Science]]) -> 468 | K82: 500 | L82: =(J82/K82)*100 -> 93.6 | M82: =IF(L82>=90,"A Grade",IF(L82>=75,"B Grade",IF(L82>=60,"C Grade",IF(L82>=50,"D Grade","Fail")))) -> A Grade
A83: STU086 | B83: Varun Bose | C83: 9A | D83: 92 | E83: 91 | F83: 73 | G83: 89 | H83: 74 | I83: 42 | J83: =SUM(Student_Dataset[[#This Row],[Mathematics]:[Computer Science]]) -> 461 | K83: 500 | L83: =(J83/K83)*100 -> 92.2 | M83: =IF(L83>=90,"A Grade",IF(L83>=75,"B Grade",IF(L83>=60,"C Grade",IF(L83>=50,"D Grade","Fail")))) -> A Grade
A84: STU126 | B84: Sakshi Kumar | C84: 9A | D84: 93 | E84: 82 | F84: 88 | G84: 54 | H84: 88 | I84: 47 | J84: =SUM(Student_Dataset[[#This Row],[Mathematics]:[Computer Science]]) -> 452 | K84: 500 | L84: =(J84/K84)*100 -> 90.4 | M84: =IF(L84>=90,"A Grade",IF(L84>=75,"B Grade",IF(L84>=60,"C Grade",IF(L84>=50,"D Grade","Fail")))) -> A Grade
...

Sheet Student Dataset (2)
A1: Student ID | B1: STU001 | C1: STU002 | D1: STU003 | E1: STU004 | F1: STU005 | G1: STU006 | H1: STU007 | I1: STU008 | J1: STU009 | K1: STU010 | L1: STU011 | M1: STU012 | N1: STU013 | O1: STU014 | P1: STU015 | Q1: STU016 | R1: STU017 | S1: STU018 | T1: STU019 | U1: STU020 | V1: STU021 | W1: STU022 | X1: STU023 | Y1: STU024 | Z1: STU025 | AA1: STU026 | AB1: STU027 | AC1: STU028 | AD1: STU029 | AE1: STU030 | AF1: STU031 | AG1: STU032 | AH1: STU033 | AI1: STU034 | AJ1: STU035 | AK1: STU036 | AL1: STU037 | AM1: STU038 | AN1: STU039 | AO1: STU040 | AP1: STU041 | AQ1: STU042 | AR1: STU043 | AS1: STU044 | AT1: STU045 | AU1: STU046 | AV1: STU047 | AW1: STU048 | AX1: STU049 | AY1: STU050 | AZ1: STU051 | BA1: STU052 | BB1: STU053 | BC1: STU054 | BD1: STU055 | BE1: STU056 | BF1: STU057 | BG1: STU058 | BH1: STU059 | BI1: STU060 | BJ1: STU061 | BK1: STU062 | BL1: STU063 | BM1: STU064 | BN1: STU065 | BO1: STU066 | BP1: STU067 | BQ1: STU068 | BR1: STU069 | BS1: STU070 | BT1: STU071 | BU1: STU072 | BV1: STU073 | BW1: STU074 | BX1: STU075 | BY1: STU076 | BZ1: STU077 | CA1: STU078 | CB1: STU079 | CC1: STU080 | CD1: STU081 | CE1: STU082 | CF1: STU083 | CG1: STU084 | CH1: STU085 | CI1: STU086 | CJ1: STU087 | CK1: STU088 | CL1: STU089 | CM1: STU090 | CN1: STU091 | CO1: STU092 | CP1: STU093 | CQ1: STU094 | CR1: STU095 | CS1: STU096 | CT1: STU097 | CU1: STU098 | CV1: STU099 | CW1: STU100 | CX1: STU101 | CY1: STU102 | CZ1: STU103 | DA1: STU104 | DB1: STU105 | DC1: STU106 | DD1: STU107 | DE1: STU108 | DF1: STU109 | DG1: STU110 | DH1: STU111 | DI1: STU112 | DJ1: STU113 | DK1: STU114 | DL1: STU115 | DM1: STU116 | DN1: STU117 | DO1: STU118 | DP1: STU119 | DQ1: STU120 | DR1: STU121 | DS1: STU122 | DT1: STU123 | DU1: STU124 | DV1: STU125 | DW1: STU126 | DX1: STU127 | DY1: STU128 | DZ1: STU129 | EA1: STU130 | EB1: STU131 | EC1: STU132 | ED1: STU133 | EE1: STU134 | EF1: STU135 | EG1: STU136 | EH1: STU137 | EI1: STU138 | EJ1: STU139 | EK1: STU140 | EL1: STU141 | EM1: STU142 | EN1: STU143 | EO1: STU144 | EP1: STU145 | EQ1: STU146 | ER1: STU147 | ES1: STU148 | ET1: STU149 | EU1: STU150
A2: Student Name | B2: Mohammed Singh | C2: Deepika Tiwari | D2: Sneha Mehta | E2: Aryan Tiwari | F2: Kavya Singh | G2: Sai Nair | H2: Sai Bhatia | I2: Priya Mishra | J2: Kavya Chauhan | K2: Aanya Chauhan | L2: Ishaan Chauhan | M2: Krishna Bose | N2: Nandini Gupta | O2: Varun Desai | P2: Rahul Chopra | Q2: Nandini Mehta | R2: Ayaan Dhawan | S2: Rahul Dubey | T2: Dhruv Dhawan | U2: Ayaan Joshi | V2: Arjun Jain | W2: Ritvik Chauhan | X2: Advik Singh | Y2: Imran Desai | Z2: Advik Nair | AA2: Arjun Pandey | AB2: Shreya Dubey | AC2: Kavya Chauhan | AD2: Dhruv Verma | AE2: Ishita Patel | AF2: Aanya Singh | AG2: Dhruv Shah | AH2: Ananya Dhawan | AI2: Aarush Kumar | AJ2: Sakshi Jain | AK2: Reyansh Saxena | AL2: Imran Desai | AM2: Darsh Verma | AN2: Sneha Sharma | AO2: Krishna Verma | AP2: Riya Malhotra | AQ2: Vivaan Patel | AR2: Aditya Bhatia | AS2: Kabir Sharma | AT2: Zaid Bose | AU2: Aditya Singh | AV2: Kavya Chopra | AW2: Priya Tiwari | AX2: Faraz Tiwari | AY2: Imran Saxena | AZ2: Nisha Kapoor | BA2: Kiara Kapoor | BB2: Imran Yadav | BC2: Ruhi Bhatia | BD2: Ritvik Kumar | BE2: Sneha Joshi | BF2: Nisha Arora | BG2: Mohammed Chauhan | BH2: Ritvik Chauhan | BI2: Aryan Kumar | BJ2: Vihaan Mehta | BK2: Rohan Malhotra | BL2: Navya Sharma | BM2: Aanya Reddy | BN2: Vihaan Chauhan | BO2: Darsh Malhotra | BP2: Kabir Desai | BQ2: Ritvik Kumar | BR2: Nandini Iyer | BS2: Aanya Jain | BT2: Riya Nair | BU2: Navya Singh | BV2: Ruhi Kapoor | BW2: Sai Chauhan | BX2: Ananya Patel | BY2: Sneha Sharma | BZ2: Aryan Dubey | CA2: Aryan Joshi | CB2: Aryan Pandey | CC2: Ayaan Saxena | CD2: Reyansh Arora | CE2: Sameer Nair | CF2: Reyansh Bhatia | CG2: Vihaan Chauhan | CH2: Ishaan Kumar | CI2: Varun Bose | CJ2: Ruhi Saxena | CK2: Atharva Nair | CL2: Aditya Joshi | CM2: Nisha Singh | CN2: Shaurya Kapoor | CO2: Darsh Bose | CP2: Nandini Chauhan | CQ2: Kiara Bose | CR2: Riya Tiwari | CS2: Pranav Shah | CT2: Ayaan Malhotra | CU2: Ishita Mishra | CV2: Pranav Pandey | CW2: Sneha Tiwari | CX2: Sameer Yadav | CY2: Sneha Kumar | CZ2: Diya Dhawan | DA2: Pooja Nair | DB2: Aryan Joshi | DC2: Sameer Dhawan | DD2: Deepika Agarwal | DE2: Zaid Kumar | DF2: Imran Bhatia | DG2: Mohammed Shah | DH2: Shaurya Jain | DI2: Priya Tiwari | DJ2: Ruhi Bhatia | DK2: Meera Chauhan | DL2: Deepika Yadav | DM2: Reyansh Joshi | DN2: Aarav Reddy | DO2: Ruhi Chauhan | DP2: Rahul Kumar | DQ2: Sakshi Chopra | DR2: Nikhil Bhatia | DS2: Sneha Mishra | DT2: Imran Saxena | DU2: Ruhi Chopra | DV2: Ayaan Kumar | DW2: Sakshi Kumar | DX2: Navya Iyer | DY2: Ritvik Bhatia | DZ2: Advik Singh | EA2: Krishna Kapoor | EB2: Varun Kumar | EC2: Ayaan Shah | ED2: Atharva Chauhan | EE2: Varun Mishra | EF2: Meera Desai | EG2: Sameer Dhawan | EH2: Darsh Iyer | EI2: Reyansh Kapoor | EJ2: Meera Srivastava | EK2: Ishaan Shah | EL2: Nikhil Saxena | EM2: Faraz Malhotra | EN2: Dhruv Kumar | EO2: Aditi Joshi | EP2: Diya Mishra | EQ2: Sai Saxena | ER2: Priya Yadav | ES2: Darsh Pandey | ET2: Ayaan Mishra | EU2: Aanya Iyer
A3: Class | B3: 6A | C3: 6A | D3: 10A | E3: 8B | F3: 8B | G3: 8A | H3: 7B | I3: 7B | J3: 10A | K3: 6B | L3: 7A | M3: 9B | N3: 9A | O3: 8B | P3: 8A | Q3: 7A | R3: 8B | S3: 6B | T3: 10A | U3: 7B | V3: 6A | W3: 9B | X3: 6B | Y3: 6B | Z3: 9B | AA3: 10A | AB3: 9B | AC3: 9B | AD3: 10B | AE3: 6A | AF3: 10B | AG3: 8B | AH3: 6B | AI3: 8B | AJ3: 8A | AK3: 10A | AL3: 8A | AM3: 6A | AN3: 6B | AO3: 8A | AP3: 10A | AQ3: 8B | AR3: 9B | AS3: 7B | AT3: 9A | AU3: 10B | AV3: 10B | AW3: 6B | AX3: 8B | AY3: 7A | AZ3: 10B | BA3: 7A | BB3: 7B | BC3: 6B | BD3: 6A | BE3: 6B | BF3: 10A | BG3: 10A | BH3: 8B | BI3: 7B | BJ3: 9A | BK3: 9A | BL3: 9A | BM3: 10B | BN3: 9A | BO3: 9A | BP3: 6B | BQ3: 9B | BR3: 6B | BS3: 7B | BT3: 9A | BU3: 9A | BV3: 10A | BW3: 9B | BX3: 9B | BY3: 10A | BZ3: 9B | CA3: 8A | CB3: 8A | CC3: 10A | CD3: 7B | CE3: 7A | CF3: 6A | CG3: 9B | CH3: 10B | CI3: 9A | CJ3: 6B | CK3: 6B | CL3: 8A | CM3: 10A | CN3: 8A | CO3: 10A | CP3: 6A | CQ3: 9B | CR3: 8B | CS3: 9A | CT3: 9A | CU3: 10B | CV3: 9B | CW3: 6B | CX3: 10A | CY3: 9A | CZ3: 10A | DA3: 9B | DB3: 10B | DC3: 9A | DD3: 6B | DE3: 6B | DF3: 10A | DG3: 8A | DH3: 8A | DI3: 7A | DJ3: 9A | DK3: 6A | DL3: 9A | DM3: 9A | DN3: 6A | DO3: 7A | DP3: 6B | DQ3: 8B | DR3: 8B | DS3: 6B | DT3: 8A | DU3: 10A | DV3: 6A | DW3: 9A | DX3: 9A | DY3: 8B | DZ3: 9B | EA3: 10B | EB3: 10B | EC3: 6A | ED3: 6A | EE3: 10A | EF3: 6A | EG3: 9B | EH3: 10B | EI3: 6B | EJ3: 9A | EK3: 9B | EL3: 8B | EM3: 9A | EN3: 9B | EO3: 9A | EP3: 6A | EQ3: 10A | ER3: 8B | ES3: 9A | ET3: 9A | EU3: 6A
A4: Mathematics | B4: 70 | C4: 38 | D4: 88 | E4: 70 | F4: 79 | G4: 81 | H4: 47 | I4: 69 | J4: 63 | K4: 62 | L4: 66 | M4: 46 | N4: 83 | O4: 49 | P4: 99 | Q4: 82 | R4: 74 | S4: 51 | T4: 60 | U4: 43 | V4: 64 | W4: 62 | X4: 90 | Y4: 42 | Z4: 52 | AA4: 47 | AB4: 62 | AC4: 71 | AD4: 42 | AE4: 100 | AF4: 66 | AG4: 65 | AH4: 36 | AI4: 43 | AJ4: 36 | AK4: 54 | AL4: 99 | AM4: 77 | AN4: 44 | AO4: 81 | AP4: 87 | AQ4: 87 | AR4: 63 | AS4: 86 | AT4: 77 | AU4: 90 | AV4: 59 | AW4: 77 | AX4: 86 | AY4: 73 | AZ4: 76 | BA4: 45 | BB4: 60 | BC4: 93 | BD4: 48 | BE4: 93 | BF4: 92 | BG4: 97 | BH4: 75 | BI4: 43 | BJ4: 84 | BK4: 88 | BL4: 78 | BM4: 38 | BN4: 76 | BO4: 67 | BP4: 40 | BQ4: 49 | BR4: 55 | BS4: 44 | BT4: 82 | BU4: 81 | BV4: 96 | BW4: 66 | BX4: 62 | BY4: 59 | BZ4: 92 | CA4: 82 | CB4: 74 | CC4: 58 | CD4: 72 | CE4: 70 | CF4: 71 | CG4: 49 | CH4: 73 | CI4: 92 | CJ4: 61 | CK4: 55 | CL4: 71 | CM4: 63 | CN4: 71 | CO4: 98 | CP4: 46 | CQ4: 70 | CR4: 76 | CS4: 39 | CT4: 100 | CU4: 98 | CV4: 50 | CW4: 63 | CX4: 69 | CY4: 59 | CZ4: 69 | DA4: 79 | DB4: 84 | DC4: 84 | DD4: 91 | DE4: 95 | DF4: 83 | DG4: 64 | DH4: 38 | DI4: 66 | DJ4: 65 | DK4: 94 | DL4: 67 | DM4: 80 | DN4: 98 | DO4: 47 | DP4: 72 | DQ4: 99 | DR4: 49 | DS4: 85 | DT4: 83 | DU4: 76 | DV4: 39 | DW4: 93 | DX4: 70 | DY4: 47 | DZ4: 46 | EA4: 61 | EB4: 35 | EC4: 51 | ED4: 51 | EE4: 48 | EF4: 42 | EG4: 44 | EH4: 76 | EI4: 62 | EJ4: 47 | EK4: 43 | EL4: 51 | EM4: 41 | EN4: 63 | EO4: 38 | EP4: 58 | EQ4: 62 | ER4: 45 | ES4: 97 | ET4: 49 | EU4: 35
A5: Science | B5: 66 | C5: 46 | D5: 63 | E5: 54 | F5: 68 | G5: 59 | H5: 83 | I5: 44 | J5: 76 | K5: 75 | L5: 68 | M5: 41 | N5: 94 | O5: 72 | P5: 57 | Q5: 55 | R5: 65 | S5: 51 | T5: 74 | U5: 78 | V5: 43 | W5: 51 | X5: 80 | Y5: 86 | Z5: 89 | AA5: 41 | AB5: 86 | AC5: 89 | AD5: 75 | AE5: 45 | AF5: 40 | AG5: 68 | AH5: 93 | AI5: 66 | AJ5: 73 | AK5: 69 | AL5: 97 | AM5: 51 | AN5: 54 | AO5: 40 | AP5: 54 | AQ5: 66 | AR5: 60 | AS5: 77 | AT5: 38 | AU5: 79 | AV5: 67 | AW5: 75 | AX5: 72 | AY5: 86 | AZ5: 94 | BA5: 71 | BB5: 53 | BC5: 88 | BD5: 89 | BE5: 52 | BF5: 55 | BG5: 65 | BH5: 45 | BI5: 88 | BJ5: 37 | BK5: 63 | BL5: 86 | BM5: 45 | BN5: 62 | BO5: 45 | BP5: 38 | BQ5: 62 | BR5: 74 | BS5: 66 | BT5: 43 | BU5: 93 | BV5: 94 | BW5: 94 | BX5: 80 | BY5: 45 | BZ5: 37 | CA5: 95 | CB5: 67 | CC5: 59 | CD5: 64 | CE5: 40 | CF5: 95 | CG5: 43 | CH5: 45 | CI5: 91 | CJ5: 62 | CK5: 35 | CL5: 93 | CM5: 54 | CN5: 91 | CO5: 91 | CP5: 64 | CQ5: 58 | CR5: 48 | CS5: 93 | CT5: 35 | CU5: 91 | CV5: 38 | CW5: 49 | CX5: 88 | CY5: 100 | CZ5: 35 | DA5: 77 | DB5: 64 | DC5: 54 | DD5: 47 | DE5: 68 | DF5: 75 | DG5: 46 | DH5: 40 | DI5: 87 | DJ5: 98 | DK5: 71 | DL5: 93 | DM5: 72 | DN5: 71 | DO5: 40 | DP5: 76 | DQ5: 69 | DR5: 94 | DS5: 36 | DT5: 82 | DU5: 63 | DV5: 73 | DW5: 82 | DX5: 39 | DY5: 82 | DZ5: 62 | EA5: 43 | EB5: 70 | EC5: 36 | ED5: 88 | EE5: 92 | EF5: 96 | EG5: 45 | EH5: 83 | EI5: 90 | EJ5: 75 | EK5: 46 | EL5: 42 | EM5: 71 | EN5: 48 | EO5: 69 | EP5: 53 | EQ5: 83 | ER5: 41 | ES5: 91 | ET5: 71 | EU5: 61
A6: English | B6: 63 | C6: 62 | D6: 92 | E6: 62 | F6: 40 | G6: 43 | H6: 70 | I6: 56 | J6: 42 | K6: 62 | L6: 89 | M6: 49 | N6: 67 | O6: 90 | P6: 99 | Q6: 35 | R6: 42 | S6: 95 | T6: 86 | U6: 37 | V6: 39 | W6: 95 | X6: 89 | Y6: 78 | Z6: 58 | AA6: 36 | AB6: 42 | AC6: 97 | AD6: 42 | AE6: 58 | AF6: 45 | AG6: 85 | AH6: 47 | AI6: 82 | AJ6: 48 | AK6: 71 | AL6: 67 | AM6: 68 | AN6: 39 | AO6: 80 | AP6: 65 | AQ6: 69 | AR6: 93 | AS6: 70 | AT6: 49 | AU6: 75 | AV6: 40 | AW6: 50 | AX6: 51 | AY6: 35 | AZ6: 91 | BA6: 100 | BB6: 38 | BC6: 59 | BD6: 63 | BE6: 94 | BF6: 95 | BG6: 70 | BH6: 52 | BI6: 87 | BJ6: 83 | BK6: 97 | BL6: 56 | BM6: 89 | BN6: 93 | BO6: 95 | BP6: 66 | BQ6: 94 | BR6: 48 | BS6: 48 | BT6: 99 | BU6: 54 | BV6: 90 | BW6: 83 | BX6: 68 | BY6: 65 | BZ6: 46 | CA6: 79 | CB6: 64 | CC6: 62 | CD6: 81 | CE6: 41 | CF6: 96 | CG6: 86 | CH6: 66 | CI6: 73 | CJ6: 68 | CK6: 87 | CL6: 44 | CM6: 69 | CN6: 50 | CO6: 45 | CP6: 37 | CQ6: 90 | CR6: 55 | CS6: 46 | CT6: 94 | CU6: 41 | CV6: 65 | CW6: 94 | CX6: 96 | CY6: 52 | CZ6: 71 | DA6: 83 | DB6: 87 | DC6: 98 | DD6: 93 | DE6: 78 | DF6: 97 | DG6: 90 | DH6: 76 | DI6: 58 | DJ6: 53 | DK6: 55 | DL6: 73 | DM6: 72 | DN6: 64 | DO6: 74 | DP6: 88 | DQ6: 56 | DR6: 44 | DS6: 68 | DT6: 48 | DU6: 43 | DV6: 98 | DW6: 88 | DX6: 82 | DY6: 80 | DZ6: 37 | EA6: 61 | EB6: 53 | EC6: 80 | ED6: 49 | EE6: 99 | EF6: 86 | EG6: 76 | EH6: 72 | EI6: 92 | EJ6: 89 | EK6: 45 | EL6: 77 | EM6: 74 | EN6: 79 | EO6: 38 | EP6: 86 | EQ6: 88 | ER6: 54 | ES6: 88 | ET6: 97 | EU6: 73
A7: Hindi | B7: 52 | C7: 64 | D7: 70 | E7: 78 | F7: 93 | G7: 40 | H7: 93 | I7: 66 | J7: 64 | K7: 98 | L7: 86 | M7: 54 | N7: 36 | O7: 55 | P7: 48 | Q7: 76 | R7: 65 | S7: 56 | T7: 82 | U7: 64 | V7: 77 | W7: 66 | X7: 87 | Y7: 48 | Z7: 70 | AA7: 46 | AB7: 56 | AC7: 54 | AD7: 41 | AE7: 43 | AF7: 88 | AG7: 51 | AH7: 44 | AI7: 71 | AJ7: 52 | AK7: 61 | AL7: 41 | AM7: 55 | AN7: 82 | AO7: 61 | AP7: 55 | AQ7: 55 | AR7: 79 | AS7: 43 | AT7: 68 | AU7: 90 | AV7: 90 | AW7: 73 | AX7: 59 | AY7: 73 | AZ7: 91 | BA7: 77 | BB7: 40 | BC7: 84 | BD7: 57 | BE7: 75 | BF7: 92 | BG7: 91 | BH7: 54 | BI7: 77 | BJ7: 96 | BK7: 63 | BL7: 94 | BM7: 52 | BN7: 76 | BO7: 37 | BP7: 60 | BQ7: 67 | BR7: 38 | BS7: 73 | BT7: 78 | BU7: 90 | BV7: 69 | BW7: 78 | BX7: 78 | BY7: 87 | BZ7: 72 | CA7: 89 | CB7: 50 | CC7: 96 | CD7: 57 | CE7: 72 | CF7: 91 | CG7: 97 | CH7: 50 | CI7: 89 | CJ7: 45 | CK7: 92 | CL7: 64 | CM7: 53 | CN7: 94 | CO7: 40 | CP7: 69 | CQ7: 97 | CR7: 77 | CS7: 75 | CT7: 87 | CU7: 61 | CV7: 55 | CW7: 50 | CX7: 95 | CY7: 43 | CZ7: 73 | DA7: 93 | DB7: 40 | DC7: 39 | DD7: 36 | DE7: 85 | DF7: 39 | DG7: 47 | DH7: 42 | DI7: 56 | DJ7: 64 | DK7: 44 | DL7: 60 | DM7: 37 | DN7: 80 | DO7: 91 | DP7: 57 | DQ7: 67 | DR7: 53 | DS7: 50 | DT7: 64 | DU7: 94 | DV7: 49 | DW7: 54 | DX7: 62 | DY7: 42 | DZ7: 41 | EA7: 62 | EB7: 51 | EC7: 65 | ED7: 43 | EE7: 63 | EF7: 89 | EG7: 53 | EH7: 93 | EI7: 64 | EJ7: 75 | EK7: 46 | EL7: 50 | EM7: 80 | EN7: 82 | EO7: 58 | EP7: 43 | EQ7: 93 | ER7: 55 | ES7: 69 | ET7: 74 | EU7: 62
